2018-02-12 21:12:26,384 ERROR: Exception on /edit_profile [POST] [in /home/jb/.virtualenvs/flask_mega_tutorial/lib/python3.5/site-packages/flask/app.py:1560]
Traceback (most recent call last):
  File "/home/jb/.virtualenvs/flask_mega_tutorial/lib/python3.5/site-packages/flask/app.py", line 1982, in wsgi_app
    response = self.full_dispatch_request()
  File "/home/jb/.virtualenvs/flask_mega_tutorial/lib/python3.5/site-packages/flask/app.py", line 1614, in full_dispatch_request
    rv = self.handle_user_exception(e)
  File "/home/jb/.virtualenvs/flask_mega_tutorial/lib/python3.5/site-packages/flask/app.py", line 1517, in handle_user_exception
    reraise(exc_type, exc_value, tb)
  File "/home/jb/.virtualenvs/flask_mega_tutorial/lib/python3.5/site-packages/flask/_compat.py", line 33, in reraise
    raise value
  File "/home/jb/.virtualenvs/flask_mega_tutorial/lib/python3.5/site-packages/flask/app.py", line 1612, in full_dispatch_request
    rv = self.dispatch_request()
  File "/home/jb/.virtualenvs/flask_mega_tutorial/lib/python3.5/site-packages/flask/app.py", line 1598, in dispatch_request
    return self.view_functions[rule.endpoint](**req.view_args)
  File "/home/jb/.virtualenvs/flask_mega_tutorial/lib/python3.5/site-packages/flask_login/utils.py", line 261, in decorated_view
    return func(*args, **kwargs)
  File "/home/jb/git_local/path_chat/app/routes.py", line 132, in edit_profile
    if form.validate_on_submit():
  File "/home/jb/.virtualenvs/flask_mega_tutorial/lib/python3.5/site-packages/flask_wtf/form.py", line 101, in validate_on_submit
    return self.is_submitted() and self.validate()
  File "/home/jb/.virtualenvs/flask_mega_tutorial/lib/python3.5/site-packages/wtforms/form.py", line 310, in validate
    return super(Form, self).validate(extra)
  File "/home/jb/.virtualenvs/flask_mega_tutorial/lib/python3.5/site-packages/wtforms/form.py", line 152, in validate
    if not field.validate(self, extra):
  File "/home/jb/.virtualenvs/flask_mega_tutorial/lib/python3.5/site-packages/wtforms/fields/core.py", line 204, in validate
    stop_validation = self._run_validation_chain(form, chain)
  File "/home/jb/.virtualenvs/flask_mega_tutorial/lib/python3.5/site-packages/wtforms/fields/core.py", line 224, in _run_validation_chain
    validator(form, self)
  File "/home/jb/git_local/path_chat/app/forms.py", line 77, in validate_password
    if not current_user.check_password(form.password.data):
NameError: name 'current_user' is not defined
2018-02-12 21:15:15,465 INFO: Microblog startup [in /home/jb/git_local/path_chat/app/__init__.py:52]
2018-02-12 21:15:28,463 ERROR: Exception on /edit_profile [POST] [in /home/jb/.virtualenvs/flask_mega_tutorial/lib/python3.5/site-packages/flask/app.py:1560]
Traceback (most recent call last):
  File "/home/jb/.virtualenvs/flask_mega_tutorial/lib/python3.5/site-packages/flask/app.py", line 1982, in wsgi_app
    response = self.full_dispatch_request()
  File "/home/jb/.virtualenvs/flask_mega_tutorial/lib/python3.5/site-packages/flask/app.py", line 1614, in full_dispatch_request
    rv = self.handle_user_exception(e)
  File "/home/jb/.virtualenvs/flask_mega_tutorial/lib/python3.5/site-packages/flask/app.py", line 1517, in handle_user_exception
    reraise(exc_type, exc_value, tb)
  File "/home/jb/.virtualenvs/flask_mega_tutorial/lib/python3.5/site-packages/flask/_compat.py", line 33, in reraise
    raise value
  File "/home/jb/.virtualenvs/flask_mega_tutorial/lib/python3.5/site-packages/flask/app.py", line 1612, in full_dispatch_request
    rv = self.dispatch_request()
  File "/home/jb/.virtualenvs/flask_mega_tutorial/lib/python3.5/site-packages/flask/app.py", line 1598, in dispatch_request
    return self.view_functions[rule.endpoint](**req.view_args)
  File "/home/jb/.virtualenvs/flask_mega_tutorial/lib/python3.5/site-packages/flask_login/utils.py", line 261, in decorated_view
    return func(*args, **kwargs)
  File "/home/jb/git_local/path_chat/app/routes.py", line 132, in edit_profile
    if form.validate_on_submit():
  File "/home/jb/.virtualenvs/flask_mega_tutorial/lib/python3.5/site-packages/flask_wtf/form.py", line 101, in validate_on_submit
    return self.is_submitted() and self.validate()
  File "/home/jb/.virtualenvs/flask_mega_tutorial/lib/python3.5/site-packages/wtforms/form.py", line 310, in validate
    return super(Form, self).validate(extra)
  File "/home/jb/.virtualenvs/flask_mega_tutorial/lib/python3.5/site-packages/wtforms/form.py", line 152, in validate
    if not field.validate(self, extra):
  File "/home/jb/.virtualenvs/flask_mega_tutorial/lib/python3.5/site-packages/wtforms/fields/core.py", line 204, in validate
    stop_validation = self._run_validation_chain(form, chain)
  File "/home/jb/.virtualenvs/flask_mega_tutorial/lib/python3.5/site-packages/wtforms/fields/core.py", line 224, in _run_validation_chain
    validator(form, self)
  File "/home/jb/git_local/path_chat/app/forms.py", line 77, in validate_password
    if not self.current_user.check_password(form.password.data):
AttributeError: 'PasswordField' object has no attribute 'current_user'
2018-02-13 18:04:11,098 INFO: Microblog startup [in /home/jb/git_local/path_chat/app/__init__.py:52]
2018-02-13 18:22:10,505 INFO: Microblog startup [in /home/jb/git_local/path_chat/app/__init__.py:52]
2018-02-13 18:22:38,687 ERROR: Exception on /change_password [GET] [in /home/jb/.virtualenvs/flask_mega_tutorial/lib/python3.5/site-packages/flask/app.py:1560]
Traceback (most recent call last):
  File "/home/jb/.virtualenvs/flask_mega_tutorial/lib/python3.5/site-packages/flask/app.py", line 1982, in wsgi_app
    response = self.full_dispatch_request()
  File "/home/jb/.virtualenvs/flask_mega_tutorial/lib/python3.5/site-packages/flask/app.py", line 1614, in full_dispatch_request
    rv = self.handle_user_exception(e)
  File "/home/jb/.virtualenvs/flask_mega_tutorial/lib/python3.5/site-packages/flask/app.py", line 1517, in handle_user_exception
    reraise(exc_type, exc_value, tb)
  File "/home/jb/.virtualenvs/flask_mega_tutorial/lib/python3.5/site-packages/flask/_compat.py", line 33, in reraise
    raise value
  File "/home/jb/.virtualenvs/flask_mega_tutorial/lib/python3.5/site-packages/flask/app.py", line 1612, in full_dispatch_request
    rv = self.dispatch_request()
  File "/home/jb/.virtualenvs/flask_mega_tutorial/lib/python3.5/site-packages/flask/app.py", line 1598, in dispatch_request
    return self.view_functions[rule.endpoint](**req.view_args)
  File "/home/jb/.virtualenvs/flask_mega_tutorial/lib/python3.5/site-packages/flask_login/utils.py", line 261, in decorated_view
    return func(*args, **kwargs)
  File "/home/jb/git_local/path_chat/app/routes.py", line 126, in change_password
    return render_template('change_password.html', form=form)
  File "/home/jb/.virtualenvs/flask_mega_tutorial/lib/python3.5/site-packages/flask/templating.py", line 133, in render_template
    return _render(ctx.app.jinja_env.get_or_select_template(template_name_or_list),
  File "/home/jb/.virtualenvs/flask_mega_tutorial/lib/python3.5/site-packages/jinja2/environment.py", line 869, in get_or_select_template
    return self.get_template(template_name_or_list, parent, globals)
  File "/home/jb/.virtualenvs/flask_mega_tutorial/lib/python3.5/site-packages/jinja2/environment.py", line 830, in get_template
    return self._load_template(name, self.make_globals(globals))
  File "/home/jb/.virtualenvs/flask_mega_tutorial/lib/python3.5/site-packages/jinja2/environment.py", line 804, in _load_template
    template = self.loader.load(self, name, globals)
  File "/home/jb/.virtualenvs/flask_mega_tutorial/lib/python3.5/site-packages/jinja2/loaders.py", line 113, in load
    source, filename, uptodate = self.get_source(environment, name)
  File "/home/jb/.virtualenvs/flask_mega_tutorial/lib/python3.5/site-packages/flask/templating.py", line 57, in get_source
    return self._get_source_fast(environment, template)
  File "/home/jb/.virtualenvs/flask_mega_tutorial/lib/python3.5/site-packages/flask/templating.py", line 85, in _get_source_fast
    raise TemplateNotFound(template)
jinja2.exceptions.TemplateNotFound: change_password.html
2018-02-13 18:25:32,432 INFO: Microblog startup [in /home/jb/git_local/path_chat/app/__init__.py:52]
2018-02-13 18:27:13,516 INFO: Microblog startup [in /home/jb/git_local/path_chat/app/__init__.py:52]
